Workbook

Sheet Summary
A1: ROSSI CLUBHOUSE — WALL PANELING MATERIALS ESTIMATE (REV 3)
A2: StayLuxe · walls-only project (ceiling separate) · materials only, labor excluded · prepared May 2026 · figures approximate
A4: ESTIMATE SUMMARY — MATERIALS ONLY
A5: Component | B5: Amount | C5: Notes
A6: Wall paneling materials | B6: =Materials!E16 -> 4295 | C6: Hardboard skim, MDF grid, base cap, consumables
A7: Casing & edge treatment | B7: =Materials!E23 -> 143.4 | C7: Window re-wrap allowance + quarter-round contingency
A8: Paint & primer | B8: =Materials!E32 -> 752 | C8: Dark finish + primer + sundries
A9: TOTAL — MATERIALS | B9: =SUM(B6:B8) -> 5190.4 | C9: Recessed-panel scope, all 8 wall segments (incl. R6)
A10: Sales tax allowance (~8%) | B10: =B9*0.08 -> 415.232 | C10: Adjust to purchase location
A11: TOTAL WITH TAX | B11: =B9+B10 -> 5605.632
A13: KEY QUANTITIES
A14: Total paneled wall length | B14: =Inputs!B12/12 -> 92.625 | C14: ft
A15: Recessed panels | B15: =Inputs!B14 -> 102 | C15: panels
A16: Hardboard skim sheets (4x8) | B16: ='Trim Takeoff'!C18 -> 32 | C16: sheets
A17: 1x6 MDF boards (grid + baseboard) | B17: ='Trim Takeoff'!C9+'Trim Takeoff'!C12 -> 42 | C17: boards
A18: PVC base cap sticks (8 ft) | B18: ='Trim Takeoff'!C15 -> 143 | C18: sticks
A19: Finish paint | B19: =Materials!B28 -> 6 | C19: gal
A21: WHAT CHANGED IN REV 3 & KEY NOTES
A22: WALLS-ONLY PROJECT. Faux ceiling beams are removed entirely — the ceiling is now a separate project
A23: with its own packet, survey (lights, HVAC, attic access) and estimate.
A24: R6 ADDED: the inside-L wall (bedroom entry to inside corner), missed in earlier revisions. The small
A25: bathroom's living-room door is sealed and paneled over; the bedroom keeps its entry as a cased opening.
A26: R6 adds ~10'-10" of wall, 4 bays, 12 panels. New total: 34 bays, 102 panels across 8 wall segments.
A27: CASING: existing window/door casing is kept and painted the dark color (not re-cased). A small flat-stock
A28: allowance covers re-wrapping 1-2 windows only if a profile is too bulky to paint out cleanly.
A29: CEILING EDGE: flat top rail, no cove/cap profile — this matches the Jenna Sue full-wainscoting reference.
A30: Quarter-round is carried as a contingency line only, to scribe an uneven ceiling line if needed.
A31: Base-cap waste raised to 18% (from 15%) to match the real-world ~1.8 sticks/panel rate in the Jenna Sue build.
A32: Baseboard: existing contractor-grade base is removed and fully replaced with new 1x6 MDF to match the grid.
... A38: area) on site before ordering.

Sheet Inputs
A1: ROSSI CLUBHOUSE — WALL PANELING MATERIALS ESTIMATE (REV 3)
A2: Walls-only project · R6 added, faux beams removed · hardboard skim + ripped-MDF grid · blue = editable input · yellow = confirm on site
A3: GEOMETRY (from carpenter hand-off packet)
A4: Ceiling height | B4: 95.75 | C4: in | D4: Measured 7'-11¾"
A5: Baseboard height | B5: 5.5 | C5: in | D5: 1x6 MDF on the flat
A6: Trim / rail face width | B6: 2.5 | C6: in | D6: Ripped from 1x6 MDF
A7: Row B square opening | B7: 30 | C7: in | D7: Fixed hero panel
A8: Rows A & C opening (each) | B8: 25.125 | C8: in | D8: Equals (ceiling - base - 4 rails - 30) / 2
A9: Paneled field height (above baseboard) | B9: 90.25 | C9: in | D9: Ceiling height minus baseboard
A11: RUN TAKEOFF (6 runs / 8 wall segments, incl. R6)
A12: Total paneled wall length | B12: 1111.5 | C12: in | D12: R1 200 + R2 193 + R3 156 + R4 156 + R6 130.5 + R5 a/b/c 103/102/71
A13: Total bays | B13: 34 | C13: count | D13: Sum of bays across all 6 runs
A14: Total recessed panels | B14: 102 | C14: count | D14: 34 bays x 3 rows
A15: Vertical trim members (total) | B15: 42 | C15: count | D15: Sum of (bays+1) per run — one at each bay edge
A16: Horizontal rails per run | B16: 4 | C16: count | D16: Ceiling, A/B, B/C, top-of-base
A17: Number of runs (for rail count) | B17: 8 | C17: count | D17: Rails are full-length per wall segment
A19: TRIM STOCK
A20: 1x6 primed MDF board length | B20: 12 | C20: ft | D20: ReliaBilt 1x6x12 primed S4S MDF (5.5" actual width)
A21: Grid strips (rips) per board | B21: 2 | C21: count | D21: 5.5" board → 2 usable 2.5" strips after saw kerf
A22: Baseboard pieces per board | B22: 1 | C22: count | D22: Baseboard uses the full 5.5" board, not ripped
A23: PVC base cap stick length | B23: 8 | C23: ft | D23: Royal 6606 PVC base cap — recessed-panel shadow line
A25: HARDBOARD SKIN
A26: Hardboard sheet size | B26: 32 | C26: SF | D26: 4 ft x 8 ft sheet
A27: Rip-waste uplift on hardboard | B27: 0.35 | C27: % | D27: Sheets ripped to ~32" bay width → ~16" offcut per sheet
A29: WASTE FACTORS
A30: Grid trim waste (verticals + rails) | B30: 0.12 | C30: % | D30: Straight runs + cut count
A31: Base cap waste | B31: 0.18 | C31: % | D31: Many short mitered pieces — 4 per panel; ~1.8 sticks/panel real-world rate (Jenna Sue)
A32: Baseboard waste | B32: 0.12 | C32: % | D32: Full-width 1x6 base — straight runs
A34: CASING & EDGE TREATMENT
A35: Windows to re-wrap in flat stock (allowance) | B35: 2 | C35: count | D35: Insurance — paint existing casing; re-wrap only if profile too bulky
A36: Flat stock per window re-wrap | B36: 22 | C36: LF | D36: Approx. casing perimeter per window
A37: Quarter-round for uneven ceiling line (contingency) | B37: 60 | C37: LF | D37: Only if ceiling line is wavy — scribe filler
A38: Quarter-round stick length | B38: 8 | C38: ft | D38: PVC quarter-round
A40: PAINT
A41: Coats | B41: 2 | C41: count | D41: Two finish coats over the dark color
A42: Coverage per gallon (one coat) | B42: 375 | C42: SF | D42: Typical interior latex
A43: Trim-relief uplift factor | B43: 1.2 | C43: x | D43: 3-D grid relief adds surface area vs flat wall
A44: Stairwell wall area (painted — base scope) | B44: 220 | C44: SF | D44: CONFIRM — below-grade stair walls, paint only
A45: Primer allowance | B45: 3 | C45: gal | D45: Seals ripped MDF edges + hardboard + wall G patch
A47: UNIT PRICES
...

Sheet Trim Takeoff
A1: TRIM & SKIN TAKEOFF — LINEAR-FOOT & SHEET QUANTITIES
A2: All quantities flow from the Inputs tab
A3: Quantity | B3: Basis | C3: Value
A4: Vertical trim — net (LF) | B4: 42 verticals x 90.25" field height | C4: =Inputs!B15*Inputs!B9/12 -> 315.875
A5: Horizontal rails — net (LF) | B5: 4 rails x total wall length | C5: =Inputs!B16*Inputs!B12/12 -> 370.5
A6: Grid trim — net (LF) | B6: Verticals + rails | C6: =C4+C5 -> 686.375
A7: Grid trim — with waste (LF) | B7: + 12% grid waste | C7: =C6*(1+Inputs!B30) -> 768.74
A8: Trim LF per MDF board | B8: 12 ft length x 2 rips | C8: =Inputs!B20*Inputs!B21 -> 24
A9: MDF boards for grid trim | B9: Grid LF / LF per board | C9: =ROUNDUP(C7/C8,0) -> 33
A10: Baseboard — net (LF) | B10: Total wall length | C10: =Inputs!B12/12 -> 92.625
A11: Baseboard — with waste (LF) | B11: + 12% waste | C11: =C10*(1+Inputs!B32) -> 103.74
A12: MDF boards for baseboard | B12: Baseboard LF / 12 ft (full board, not ripped) | C12: =ROUNDUP(C11/Inputs!B20,0) -> 9
A13: Base cap — net (LF) | B13: Inside perimeter of all 102 recessed openings | C13: =(Inputs!B14/3)*((2*((Inputs!B12/Inputs!B13)-Inputs!B6)+2*Inputs!B8)*2+(2*((Inputs!B12/Inputs!B13)-Inputs!B6)+2*Inputs!B7))/12 -> 968
A14: Base cap — with waste (LF) | B14: + 18% waste (short mitered pieces) | C14: =C13*(1+Inputs!B31) -> 1142.24
A15: Base cap sticks (8 ft) | B15: Base cap LF / 8 ft | C15: =ROUNDUP(C14/Inputs!B23,0) -> 143
A16: Gross wall area (SF) | B16: Total length x ceiling height | C16: =Inputs!B12*Inputs!B4/144 -> 739.07031
A17: Hardboard sheets — by area | B17: Wall area / 32 SF | C17: =C16/Inputs!B26 -> 23.095947
A18: Hardboard sheets — with rip waste | B18: + 35% rip waste | C18: =ROUNDUP(C17*(1+Inputs!B27),0) -> 32
A20: NOTE: Base cap LF uses the average bay opening width across all runs. The base cap forms the recessed-panel shadow line inside every opening — 4 mitered pieces per panel, 102 panels. Hardboard is ripped to bay width so every sheet seam lands under a vertical trim member; the 35% rip-waste factor covers the ~16" offcut left when a 48" sheet is cut to ~32". Field-verify the 1,111" total wall length before ordering.

Sheet Materials
A1: MATERIALS — RECESSED-PANEL WALL SCOPE
A2: Locked design · materials only, labor excluded
A3: WALL PANELING MATERIALS
A4: Item | B4: Qty | C4: Unit | D4: Unit $ | E4: Extended $ | F4: Notes
A5: Hardboard 4x8 sheet — skim substrate | B5: ='Trim Takeoff'!C18 -> 32 | C5: sheet | D5: =Inputs!B49 -> 16 | E5: =B5*D5 -> 512 | F5: Ripped to bay width; seams fall under verticals
A6: 1x6 primed MDF — grid trim (ripped to 2.5") | B6: ='Trim Takeoff'!C9 -> 33 | C6: board | D6: =Inputs!B48 -> 29 | E6: =B6*D6 -> 957 | F6: Verticals + 4 rails per run
A7: 1x6 primed MDF — baseboard (full width) | B7: ='Trim Takeoff'!C12 -> 9 | C7: board | D7: =Inputs!B48 -> 29 | E7: =B7*D7 -> 261 | F7: 5.5" baseboard, not ripped
A8: PVC base cap moulding (8 ft) | B8: ='Trim Takeoff'!C15 -> 143 | C8: stick | D8: =Inputs!B50 -> 9.5 | E8: =B8*D8 -> 1358.5 | F8: Recessed-panel shadow line — 4 per panel, 90 panels
A9: Panel adhesive — hardboard skim | B9: =ROUNDUP('Trim Takeoff'!C16/Inputs!B64,0) -> 24 | C9: tube | D9: =Inputs!B53 -> 7.5 | E9: =B9*D9 -> 180 | F9: Skim sheets glued + nailed to studs
A10: Construction adhesive — trim | B10: =ROUNDUP('Trim Takeoff'!C6/Inputs!B63,0) -> 13 | C10: tube | D10: =Inputs!B52 -> 6.5 | E10: =B10*D10 -> 84.5 | F10: Grid trim glued + nailed to skim
A11: Finish / brad nails | B11: =ROUNDUP(('Trim Takeoff'!C6+'Trim Takeoff'!C13)/Inputs!B65,0) -> 12 | C11: pack | D11: =Inputs!B54 -> 9 | E11: =B11*D11 -> 108 | F11: Grid trim + base cap
A12: Paintable caulk | B12: =ROUNDUP(('Trim Takeoff'!C6*2+'Trim Takeoff'!C13*2)/Inputs!B66,0) -> 119 | C12: tube | D12: =Inputs!B55 -> 5 | E12: =B12*D12 -> 595 | F12: Both edges of grid + base cap miters
A13: Wood filler | B13: =MAX(3,ROUNDUP(('Trim Takeoff'!C6+'Trim Takeoff'!C13)/Inputs!B67,0)) -> 6 | C13: tub | D13: =Inputs!B56 -> 8 | E13: =B13*D13 -> 48 | F13: Nail holes — grid + base cap
A14: Outlet / switch box extenders | B14: =Inputs!B68 -> 8 | C14: pack | D14: =Inputs!B59 -> 12 | E14: =B14*D14 -> 96 | F14: Skim + trim adds wall depth at devices
A15: Misc (blades, shims, sandpaper) | B15: 1 | C15: allow | D15: =Inputs!B69 -> 95 | E15: =B15*D15 -> 95
A16: WALL PANELING MATERIALS SUBTOTAL | E16: =SUM(E5:E15) -> 4295
A18: CASING & EDGE TREATMENT
A19: Item | B19: Qty | C19: Unit | D19: Unit $ | E19: Extended $ | F19: Notes
A20: Flat casing stock — window re-wrap allowance | B20: =Inputs!B35*Inputs!B36 -> 44 | C20: LF | D20: =Inputs!B51 -> 1.6 | E20: =B20*D20 -> 70.4 | F20: Allowance: re-wrap 1-2 windows only if profile too bulky to paint
A21: PVC quarter-round — ceiling-line scribe (contingency) | B21: =ROUNDUP(Inputs!B37/Inputs!B38,0) -> 8 | C21: stick | D21: =Inputs!B60 -> 6 | E21: =B21*D21 -> 48 | F21: Only if ceiling line is wavy — carry as contingency
A22: Casing / contingency fasteners & caulk | B22: 1 | C22: allow | D22: 25 | E22: =B22*D22 -> 25
A23: CASING & EDGE TREATMENT SUBTOTAL | E23: =SUM(E20:E22) -> 143.4
A25: PAINT & PRIMER
A26: Item | B26: Qty | C26: Unit | D26: Unit $ | E26: Extended $ | F26: Notes
A27: Paintable area per coat (SF) — grid relief + stairwell | B27: =(Inputs!B12*Inputs!B4/144*Inputs!B43)+Inputs!B44 -> 1106.8844
A28: Finish paint required (gal) — all coats | B28: =ROUNDUP(B27*Inputs!B41/Inputs!B42,0) -> 6
A29: Interior finish paint — dark (Cyberspace / Charleston Green) | B29: =B28 -> 6 | C29: gal | D29: =Inputs!B57 -> 78 | E29: =B29*D29 -> 468 | F29: Includes stairwell walls (painted, base scope)
A30: Primer / bonding primer | B30: =Inputs!B45 -> 3 | C30: gal | D30: =Inputs!B58 -> 48 | E30: =B30*D30 -> 144 | F30: Seals ripped MDF edges + hardboard + wall G patch
A31: Painting sundries (rollers, brushes, trays, tape, drops) | B31: 1 | C31: allow | D31: 140 | E31: =B31*D31 -> 140
A32: PAINT & PRIMER SUBTOTAL | E32: =SUM(E29:E31) -> 752
